# 实验文档

1123：

已经完成了环境的配置，开始进行训练了

这是第一次运行之后的结果：

```shell
(KRDNenv) PS D:\ThreeCode\KRDN> python main.py --dataset alibaba-ifashion --lr 0.0001 --context_hops 3 --num_neg_sample 200 --margin 0.6 --max_iter 2
reading train and test user-item set ...
combinating train_cf and kg data ...
building the graph ...
Begin to load interaction triples ...
100%|#########################################################################################################################################################################################| 1380510/1380510 [00:02<00:00, 657180.64it/s]

Begin to load knowledge graph triples ...
100%|###########################################################################################################################################################################################| 558310/558310 [00:02<00:00, 240999.73it/s]
start training ...
start prepare feed data...
multiprocessing.pool.RemoteTraceback:
"""
Traceback (most recent call last):
  File "D:\Conda\envs\KRDNenv\lib\multiprocessing\pool.py", line 125, in worker
    result = (True, func(*args, **kwds))
  File "D:\Conda\envs\KRDNenv\lib\multiprocessing\pool.py", line 48, in mapstar
    return list(map(*args))
  File "D:\ThreeCode\KRDN\main.py", line 26, in get_neg_one
    neg_item = np.random.randint(low=0, high=n_items, size=args.num_neg_sample)
NameError: name 'args' is not defined
"""

The above exception was the direct cause of the following exception:

Traceback (most recent call last):
  File "main.py", line 101, in <module>
    all_feed_data = get_feed_data(train_cf_pairs, user_dict['train_user_set'])  # {'user': [n,], 'pos_item': [n,], 'neg_item': [n, n_sample]}
  File "main.py", line 49, in get_feed_data
    feed_dict['neg_items'] = torch.LongTensor(negative_sampling(entity_pairs,train_user_set))
  File "main.py", line 41, in negative_sampling
    neg_items = pool.map(get_neg_one, user_item.cpu().numpy()[:, 0])
  File "D:\Conda\envs\KRDNenv\lib\multiprocessing\pool.py", line 364, in map
    return self._map_async(func, iterable, mapstar, chunksize).get()
  File "D:\Conda\envs\KRDNenv\lib\multiprocessing\pool.py", line 771, in get
    raise self._value
NameError: name 'args' is not defined
```

解决问题的方式：https://blog.csdn.net/CoolBoySilverBullet/article/details/123365452

---

1124

发现了解决问题的方式，原来是多线程编程的问题

但是现在出现了一个问题，就是memory出现了问题，也就是内存不足的情况，不知道该如何解决
或许可以尝试减少训练的参数的大小，数据集的大小，或者减少batch的大小

我觉得可以先开始写报告了！
